2025-01-29 00:16:46,270 - INFO - Processing data with:
2025-01-29 00:16:46,275 - INFO - - Start date: 2014-08-01 00:00:00
2025-01-29 00:16:46,275 - INFO - - Prediction horizon: 10 days
2025-01-29 00:16:46,275 - INFO - - Train end: 2017-12-29 00:00:00
2025-01-29 00:16:46,275 - INFO - - Val end: 2018-12-28 00:00:00
2025-01-29 00:16:46,278 - INFO - - Enabled features: 97
2025-01-29 00:16:46,278 - INFO - 
Loading raw data...
2025-01-29 00:17:14,599 - INFO - 
Cleaning data...
2025-01-29 00:17:14,599 - INFO - Initial data shape: (11512867, 13)
2025-01-29 00:17:15,679 - INFO - Shape after removing missing company names: (11512867, 13)
2025-01-29 00:17:20,875 - INFO - Shape after removing days with < 8 stocks: (11460947, 13)
2025-01-29 00:17:20,875 - INFO - \Pivoting data...
2025-01-29 00:17:20,875 - INFO - Pivoting data to wide format...
2025-01-29 00:17:28,390 - WARNING - Found 3952614 duplicate entries in pivot columns
2025-01-29 00:17:31,868 - WARNING - Sample duplicates:
          GVKEY  IID  COMPANYID  ...                         FACTORNAME  FACTORVALUE   ASOFDATE
1793161  247558  01W    7687618  ...             1 Yr Chg in Admissions          NaN 2014-08-01
4403790  247558  02W    7687618  ...             1 Yr Chg in Admissions          NaN 2014-08-01
1793199  247558  01W    7687618  ...   1 Yr Chg in Number of Properties          NaN 2014-08-01
4403828  247558  02W    7687618  ...   1 Yr Chg in Number of Properties          NaN 2014-08-01
1793205  247558  01W    7687618  ...  1 Yr Chg in Number of Restuarants          NaN 2014-08-01
4403834  247558  02W    7687618  ...  1 Yr Chg in Number of Restuarants          NaN 2014-08-01
1793200  247558  01W    7687618  ...        1 Yr Chg in Number of Rooms          NaN 2014-08-01
4403829  247558  02W    7687618  ...        1 Yr Chg in Number of Rooms          NaN 2014-08-01
1793201  247558  01W    7687618  ...       1 Yr Chg in Revenue per Room          NaN 2014-08-01
4403830  247558  02W    7687618  ...       1 Yr Chg in Revenue per Room          NaN 2014-08-01

[10 rows x 13 columns]
2025-01-29 00:17:32,670 - WARNING - Duplicate entries with different FACTORVALUE values found
2025-01-29 00:17:35,467 - WARNING - Sample duplicates:
          GVKEY  IID  COMPANYID  ...                         FACTORNAME  FACTORVALUE   ASOFDATE
1793161  247558  01W    7687618  ...             1 Yr Chg in Admissions          NaN 2014-08-01
4403790  247558  02W    7687618  ...             1 Yr Chg in Admissions          NaN 2014-08-01
1793199  247558  01W    7687618  ...   1 Yr Chg in Number of Properties          NaN 2014-08-01
4403828  247558  02W    7687618  ...   1 Yr Chg in Number of Properties          NaN 2014-08-01
1793205  247558  01W    7687618  ...  1 Yr Chg in Number of Restuarants          NaN 2014-08-01
4403834  247558  02W    7687618  ...  1 Yr Chg in Number of Restuarants          NaN 2014-08-01
1793200  247558  01W    7687618  ...        1 Yr Chg in Number of Rooms          NaN 2014-08-01
4403829  247558  02W    7687618  ...        1 Yr Chg in Number of Rooms          NaN 2014-08-01
1793201  247558  01W    7687618  ...       1 Yr Chg in Revenue per Room          NaN 2014-08-01
4403830  247558  02W    7687618  ...       1 Yr Chg in Revenue per Room          NaN 2014-08-01

[10 rows x 13 columns]
2025-01-29 00:17:49,360 - INFO - Pivoted data shape: (19943, 476)
2025-01-29 00:17:54,918 - INFO - 
Selecting features...
2025-01-29 00:17:54,918 - INFO - Selecting features...
2025-01-29 00:17:54,920 - INFO - Using 31 out of 97 enabled features
2025-01-29 00:17:54,932 - INFO - 
Calculating target...
2025-01-29 00:17:54,932 - INFO - Calculating 10-day forward returns...
2025-01-29 00:17:55,314 - ERROR - Processing failed: incompatible index of inserted column with frame index
Traceback (most recent call last):
  File "C:\Users\gregb\AppData\Local\Programs\Python\Python312\Lib\site-packages\pandas\core\frame.py", line 12304, in _reindex_for_setitem
    reindexed_value = value.reindex(index)._values
                      ^^^^^^^^^^^^^^^^^^^^
  File "C:\Users\gregb\AppData\Local\Programs\Python\Python312\Lib\site-packages\pandas\core\series.py", line 4981, in reindex
    return super().reindex(
           ^^^^^^^^^^^^^^^^
  File "C:\Users\gregb\AppData\Local\Programs\Python\Python312\Lib\site-packages\pandas\core\generic.py", line 5521, in reindex
    return self._reindex_axes(
           ^^^^^^^^^^^^^^^^^^^
  File "C:\Users\gregb\AppData\Local\Programs\Python\Python312\Lib\site-packages\pandas\core\generic.py", line 5544, in _reindex_axes
    new_index, indexer = ax.reindex(
                         ^^^^^^^^^^^
  File "C:\Users\gregb\AppData\Local\Programs\Python\Python312\Lib\site-packages\pandas\core\indexes\base.py", line 4438, in reindex
    target = self._wrap_reindex_result(target, indexer, preserve_names)
             ^^^^^^^^^^^^^^^^^^^^^^^^^^^^^^^^^^^^^^^^^^^^^^^^^^^^^^^^^^
  File "C:\Users\gregb\AppData\Local\Programs\Python\Python312\Lib\site-packages\pandas\core\indexes\multi.py", line 2602, in _wrap_reindex_result
    target = MultiIndex.from_tuples(target)
             ^^^^^^^^^^^^^^^^^^^^^^^^^^^^^^
  File "C:\Users\gregb\AppData\Local\Programs\Python\Python312\Lib\site-packages\pandas\core\indexes\multi.py", line 220, in new_meth
    return meth(self_or_cls, *args, **kwargs)
           ^^^^^^^^^^^^^^^^^^^^^^^^^^^^^^^^^^
  File "C:\Users\gregb\AppData\Local\Programs\Python\Python312\Lib\site-packages\pandas\core\indexes\multi.py", line 615, in from_tuples
    arrays = list(lib.tuples_to_object_array(tuples).T)
                  ^^^^^^^^^^^^^^^^^^^^^^^^^^^^^^^^^^
  File "lib.pyx", line 2983, in pandas._libs.lib.tuples_to_object_array
ValueError: Buffer dtype mismatch, expected 'Python object' but got 'long long'

The above exception was the direct cause of the following exception:

Traceback (most recent call last):
  File "C:\Users\gregb\Downloads\Data\latest\pct_change\src\data_0_pipeline.py", line 71, in process_data
    featured_data = calculate_target(featured_data, horizon)
                    ^^^^^^^^^^^^^^^^^^^^^^^^^^^^^^^^^^^^^^^^
  File "C:\Users\gregb\Downloads\Data\latest\pct_change\src\data_2_feature_engineering.py", line 73, in calculate_target
    df['horizon_mean'] = df.groupby('COMPANYNAME').apply(get_horizon_mean)
    ~~^^^^^^^^^^^^^^^^
  File "C:\Users\gregb\AppData\Local\Programs\Python\Python312\Lib\site-packages\pandas\core\frame.py", line 4091, in __setitem__
    self._set_item(key, value)
  File "C:\Users\gregb\AppData\Local\Programs\Python\Python312\Lib\site-packages\pandas\core\frame.py", line 4300, in _set_item
    value, refs = self._sanitize_column(value)
                  ^^^^^^^^^^^^^^^^^^^^^^^^^^^^
  File "C:\Users\gregb\AppData\Local\Programs\Python\Python312\Lib\site-packages\pandas\core\frame.py", line 5036, in _sanitize_column
    return _reindex_for_setitem(value, self.index)
           ^^^^^^^^^^^^^^^^^^^^^^^^^^^^^^^^^^^^^^^
  File "C:\Users\gregb\AppData\Local\Programs\Python\Python312\Lib\site-packages\pandas\core\frame.py", line 12311, in _reindex_for_setitem
    raise TypeError(
TypeError: incompatible index of inserted column with frame index
2025-01-29 00:17:55,334 - ERROR - Pipeline failed
Traceback (most recent call last):
  File "C:\Users\gregb\AppData\Local\Programs\Python\Python312\Lib\site-packages\pandas\core\frame.py", line 12304, in _reindex_for_setitem
    reindexed_value = value.reindex(index)._values
                      ^^^^^^^^^^^^^^^^^^^^
  File "C:\Users\gregb\AppData\Local\Programs\Python\Python312\Lib\site-packages\pandas\core\series.py", line 4981, in reindex
    return super().reindex(
           ^^^^^^^^^^^^^^^^
  File "C:\Users\gregb\AppData\Local\Programs\Python\Python312\Lib\site-packages\pandas\core\generic.py", line 5521, in reindex
    return self._reindex_axes(
           ^^^^^^^^^^^^^^^^^^^
  File "C:\Users\gregb\AppData\Local\Programs\Python\Python312\Lib\site-packages\pandas\core\generic.py", line 5544, in _reindex_axes
    new_index, indexer = ax.reindex(
                         ^^^^^^^^^^^
  File "C:\Users\gregb\AppData\Local\Programs\Python\Python312\Lib\site-packages\pandas\core\indexes\base.py", line 4438, in reindex
    target = self._wrap_reindex_result(target, indexer, preserve_names)
             ^^^^^^^^^^^^^^^^^^^^^^^^^^^^^^^^^^^^^^^^^^^^^^^^^^^^^^^^^^
  File "C:\Users\gregb\AppData\Local\Programs\Python\Python312\Lib\site-packages\pandas\core\indexes\multi.py", line 2602, in _wrap_reindex_result
    target = MultiIndex.from_tuples(target)
             ^^^^^^^^^^^^^^^^^^^^^^^^^^^^^^
  File "C:\Users\gregb\AppData\Local\Programs\Python\Python312\Lib\site-packages\pandas\core\indexes\multi.py", line 220, in new_meth
    return meth(self_or_cls, *args, **kwargs)
           ^^^^^^^^^^^^^^^^^^^^^^^^^^^^^^^^^^
  File "C:\Users\gregb\AppData\Local\Programs\Python\Python312\Lib\site-packages\pandas\core\indexes\multi.py", line 615, in from_tuples
    arrays = list(lib.tuples_to_object_array(tuples).T)
                  ^^^^^^^^^^^^^^^^^^^^^^^^^^^^^^^^^^
  File "lib.pyx", line 2983, in pandas._libs.lib.tuples_to_object_array
ValueError: Buffer dtype mismatch, expected 'Python object' but got 'long long'

The above exception was the direct cause of the following exception:

Traceback (most recent call last):
  File "C:\Users\gregb\Downloads\Data\latest\pct_change\src\data_0_pipeline.py", line 107, in <module>
    process_data()
  File "C:\Users\gregb\Downloads\Data\latest\pct_change\src\data_0_pipeline.py", line 71, in process_data
    featured_data = calculate_target(featured_data, horizon)
                    ^^^^^^^^^^^^^^^^^^^^^^^^^^^^^^^^^^^^^^^^
  File "C:\Users\gregb\Downloads\Data\latest\pct_change\src\data_2_feature_engineering.py", line 73, in calculate_target
    df['horizon_mean'] = df.groupby('COMPANYNAME').apply(get_horizon_mean)
    ~~^^^^^^^^^^^^^^^^
  File "C:\Users\gregb\AppData\Local\Programs\Python\Python312\Lib\site-packages\pandas\core\frame.py", line 4091, in __setitem__
    self._set_item(key, value)
  File "C:\Users\gregb\AppData\Local\Programs\Python\Python312\Lib\site-packages\pandas\core\frame.py", line 4300, in _set_item
    value, refs = self._sanitize_column(value)
                  ^^^^^^^^^^^^^^^^^^^^^^^^^^^^
  File "C:\Users\gregb\AppData\Local\Programs\Python\Python312\Lib\site-packages\pandas\core\frame.py", line 5036, in _sanitize_column
    return _reindex_for_setitem(value, self.index)
           ^^^^^^^^^^^^^^^^^^^^^^^^^^^^^^^^^^^^^^^
  File "C:\Users\gregb\AppData\Local\Programs\Python\Python312\Lib\site-packages\pandas\core\frame.py", line 12311, in _reindex_for_setitem
    raise TypeError(
TypeError: incompatible index of inserted column with frame index
