2025-01-30 12:55:44,933 - INFO - Processing data with:
2025-01-30 12:55:44,949 - INFO - - Start date: 2014-08-01 00:00:00
2025-01-30 12:55:44,949 - INFO - - Prediction horizon: 10 days
2025-01-30 12:55:44,950 - INFO - - Train end: 2017-12-29 00:00:00
2025-01-30 12:55:44,950 - INFO - - Val end: 2018-12-28 00:00:00
2025-01-30 12:55:44,950 - INFO - - Enabled features: 472
2025-01-30 12:55:44,950 - INFO - 
Loading raw data...
2025-01-30 12:55:44,952 - ERROR - Processing failed: [Errno 2] No such file or directory: 'data/raw/raw_data.csv'
Traceback (most recent call last):
  File "C:\Users\gregb\Downloads\Data\latest\pct_change_repo\src\data_0_pipeline.py", line 55, in process_data
    raw_data = pd.read_csv(
               ^^^^^^^^^^^^
  File "C:\Users\gregb\AppData\Local\Programs\Python\Python312\Lib\site-packages\pandas\io\parsers\readers.py", line 948, in read_csv
    return _read(filepath_or_buffer, kwds)
           ^^^^^^^^^^^^^^^^^^^^^^^^^^^^^^^
  File "C:\Users\gregb\AppData\Local\Programs\Python\Python312\Lib\site-packages\pandas\io\parsers\readers.py", line 611, in _read
    parser = TextFileReader(filepath_or_buffer, **kwds)
             ^^^^^^^^^^^^^^^^^^^^^^^^^^^^^^^^^^^^^^^^^^
  File "C:\Users\gregb\AppData\Local\Programs\Python\Python312\Lib\site-packages\pandas\io\parsers\readers.py", line 1448, in __init__
    self._engine = self._make_engine(f, self.engine)
                   ^^^^^^^^^^^^^^^^^^^^^^^^^^^^^^^^^
  File "C:\Users\gregb\AppData\Local\Programs\Python\Python312\Lib\site-packages\pandas\io\parsers\readers.py", line 1705, in _make_engine
    self.handles = get_handle(
                   ^^^^^^^^^^^
  File "C:\Users\gregb\AppData\Local\Programs\Python\Python312\Lib\site-packages\pandas\io\common.py", line 863, in get_handle
    handle = open(
             ^^^^^
FileNotFoundError: [Errno 2] No such file or directory: 'data/raw/raw_data.csv'
2025-01-30 12:55:44,995 - ERROR - Pipeline failed
Traceback (most recent call last):
  File "C:\Users\gregb\Downloads\Data\latest\pct_change_repo\src\data_0_pipeline.py", line 121, in <module>
    process_data()
  File "C:\Users\gregb\Downloads\Data\latest\pct_change_repo\src\data_0_pipeline.py", line 55, in process_data
    raw_data = pd.read_csv(
               ^^^^^^^^^^^^
  File "C:\Users\gregb\AppData\Local\Programs\Python\Python312\Lib\site-packages\pandas\io\parsers\readers.py", line 948, in read_csv
    return _read(filepath_or_buffer, kwds)
           ^^^^^^^^^^^^^^^^^^^^^^^^^^^^^^^
  File "C:\Users\gregb\AppData\Local\Programs\Python\Python312\Lib\site-packages\pandas\io\parsers\readers.py", line 611, in _read
    parser = TextFileReader(filepath_or_buffer, **kwds)
             ^^^^^^^^^^^^^^^^^^^^^^^^^^^^^^^^^^^^^^^^^^
  File "C:\Users\gregb\AppData\Local\Programs\Python\Python312\Lib\site-packages\pandas\io\parsers\readers.py", line 1448, in __init__
    self._engine = self._make_engine(f, self.engine)
                   ^^^^^^^^^^^^^^^^^^^^^^^^^^^^^^^^^
  File "C:\Users\gregb\AppData\Local\Programs\Python\Python312\Lib\site-packages\pandas\io\parsers\readers.py", line 1705, in _make_engine
    self.handles = get_handle(
                   ^^^^^^^^^^^
  File "C:\Users\gregb\AppData\Local\Programs\Python\Python312\Lib\site-packages\pandas\io\common.py", line 863, in get_handle
    handle = open(
             ^^^^^
FileNotFoundError: [Errno 2] No such file or directory: 'data/raw/raw_data.csv'
